<?xml version="1.0" ?>
<!-- =================================================================================== -->
<!-- |    This document was autogenerated by xacro from youbot.urdf.xacro              | -->
<!-- |    EDITING THIS FILE BY HAND IS NOT RECOMMENDED                                 | -->
<!-- =================================================================================== -->
<robot name="youbot" xmlns:controller="http://playerstage.sourceforge.net/gazebo/xmlschema/#controller" xmlns:interface="http://playerstage.sourceforge.net/gazebo/xmlschema/#interface" xmlns:sensor="http://playerstage.sourceforge.net/gazebo/xmlschema/#sensor" xmlns:xacro="http://ros.org/wiki/xacro">
  <!-- The following xacro:included files set up definitions of parts of the robot body -->
  <!-- misc common stuff? -->
  <!-- Casters -->
  <!-- youbot base -->
  <!-- simplified box collision geometry for base -->
  <!-- youbot plate -->
  <!-- youbot arm -->
  <!-- reduction ratio doesn't affect the model-->
  <!-- reduction ratio must not to be 0-->
  &gt;

	
  <!-- common properties -->
  <!-- arm limits positions (deg) -->
  <!-- dynamic properties : mass (kg) Alu data sheet -->
  <!--<property name="link_0_mass" value="0.845" />
	<property name="link_1_mass" value="0.1" />
	<property name="link_2_mass" value="0.1" />
	<property name="link_3_mass" value="0.1" />
	<property name="link_4_mass" value="0.1" />
	<property name="link_5_mass" value="0.1" />-->
  <!-- TODO: add inertia tensor-->
  <!-- youbot gripper -->
  <!-- common properties -->
  <!-- fingers limits, values are in meters -->
  <!-- controller manager -->
  <gazebo>
    <plugin filename="libgazebo_ros_control.so" name="gazebo_ros_controller"/>
  </gazebo>
  <!-- materials for visualization -->
  <material name="youBot/Orange">
    <color rgba="1.0 0.4 0.0 1.0"/>
  </material>
  <material name="youBot/Grey">
    <color rgba="0.7 0.7 0.7 1.0"/>
  </material>
  <material name="youBot/DarkGrey">
    <color rgba="0.3 0.3 0.3 1.0"/>
  </material>
  <material name="youBot/White">
    <color rgba="1.0 1.0 1.0 1.0"/>
  </material>
  <material name="youBot/Black">
    <color rgba="0.0 0.0 0.0 1.0"/>
  </material>
  <material name="youBot/Red">
    <color rgba="1.0 0.0 0.0 1.0"/>
  </material>
  <material name="youBot/Green">
    <color rgba="0.0 1.0 0.0 1.0"/>
  </material>
  <material name="youBot/Blue">
    <color rgba="0.0 0.0 0.8 1.0"/>
  </material>
  <material name="youBot/LightGrey">
    <color rgba="0.82 0.82 0.82 1.0"/>
  </material>
  <!-- sensors -->
  <!-- Now we can start using the macros xacro:included above to define the actual youbot -->
  <!-- The first use of a macro.  This one was defined in base.urdf.xacro above.
       A macro like this will expand to a set of link and joint definitions, and to additional
       Gazebo-related extensions (sensor plugins, etc).  The macro takes an argument, name, 
       that equals "base", and uses it to generate names for its component links and joints 
       (e.g., base_link).  The xacro:included origin block is also an argument to the macro.  By convention, 
       the origin block defines where the component is w.r.t its parent (in this case the parent 
       is the world frame). For more, see http://www.ros.org/wiki/xacro -->
  <!-- foot for arm-->
  <link name="base_footprint">
    <inertial>
      <mass value="0.1"/>
      <origin rpy="0 0 0" xyz="0 0 -0.05"/>
      <inertia ixx="1.0" ixy="0.0" ixz="0.0" iyy="1.0" iyz="0.0" izz="1.0"/>
    </inertial>
    <visual>
      <origin rpy="0 0 0" xyz="0 0 0"/>
      <geometry>
        <box size="0.001 0.001 0.001"/>
      </geometry>
      <material name="youBot/Red"/>
    </visual>
    <collision>
      <origin rpy="0 0 0" xyz="0 0 -0.05"/>
      <geometry>
        <box size="0.001 0.001 0.001"/>
      </geometry>
    </collision>
  </link>
  <joint name="base_footprint_joint" type="fixed">
    <origin rpy="0 0 0" xyz="0 0 0"/>
    <child link="base_link"/>
    <parent link="base_footprint"/>
  </joint>
  <link name="base_link">
    <inertial>
      <mass value="22.0"/>
      <origin xyz="0 0 0"/>
      <inertia ixx="5.652232699207" ixy="-0.009719934438" ixz="1.293988226423" iyy="5.669473158652" iyz="-0.007379583694" izz="3.683196351726"/>
    </inertial>
    <visual>
      <origin rpy="0 0 0" xyz="0 0 0"/>
      <geometry>
        <mesh filename="package://youbot_description/meshes/youbot_base/base.dae"/>
      </geometry>
      <material name="youBot/DarkGrey"/>
    </visual>
    <collision>
      <origin rpy="0 0 0" xyz="0 0 0"/>
      <geometry>
        <!--<box size="${base_size_x} ${base_size_y} ${base_size_z}" />-->
        <mesh filename="package://youbot_description/meshes/youbot_base/base_convex.dae"/>
      </geometry>
    </collision>
  </link>
  <!-- front left wheel -->
  <joint name="caster_joint_fl" type="continuous">
    <origin rpy="0 0 0" xyz="0.228 0.158 -0.034"/>
    <axis xyz="0 0 1"/>
    <limit effort="30" velocity="10"/>
    <dynamics damping="1.0" friction="1.0"/>
    <safety_controller k_velocity="10.0"/>
    <parent link="base_link"/>
    <child link="caster_link_fl"/>
  </joint>
  <link name="caster_link_fl">
    <inertial>
      <mass value="0.1"/>
      <origin xyz="0 0 0"/>
      <inertia ixx="0.012411765597" ixy="-0.000711733678" ixz="0.00050272983" iyy="0.015218160428" iyz="-0.000004273467" izz="0.011763977943"/>
    </inertial>
  </link>
  <joint name="wheel_joint_fl" type="continuous">
    <axis xyz="0 1 0"/>
    <limit effort="30" velocity="10"/>
    <origin rpy="0 0 0" xyz="0.0 0.0 0.0"/>
    <parent link="caster_link_fl"/>
    <dynamics damping="1.0" friction="1.0"/>
    <safety_controller k_velocity="10.0"/>
    <child link="wheel_link_fl"/>
  </joint>
  <link name="wheel_link_fl">
    <inertial>
      <mass value="1.4"/>
      <origin xyz="0 0 0"/>
      <inertia ixx="0.012411765597" ixy="-0.000711733678" ixz="0.00050272983" iyy="0.015218160428" iyz="-0.000004273467" izz="0.011763977943"/>
    </inertial>
    <visual>
      <origin rpy="0 0 0" xyz="0 0 0"/>
      <!--<mesh filename="package://youbot_description/meshes/youbot_base/youbot_wheel.stl" />-->
      <geometry>
        <sphere radius="0.0475"/>
      </geometry>
      <material name="youBot/Orange"/>
    </visual>
    <collision>
      <origin rpy="1.57079632679 0 0" xyz="0 0 0"/>
      <geometry>
        <cylinder length="0.0475" radius="0.0475"/>
      </geometry>
    </collision>
  </link>
  <!-- front right wheel -->
  <joint name="caster_joint_fr" type="continuous">
    <origin rpy="0 0 0" xyz="0.228 -0.158 -0.034"/>
    <axis xyz="0 0 1"/>
    <limit effort="30" velocity="10"/>
    <dynamics damping="1.0" friction="1.0"/>
    <safety_controller k_velocity="10.0"/>
    <parent link="base_link"/>
    <child link="caster_link_fr"/>
  </joint>
  <link name="caster_link_fr">
    <inertial>
      <mass value="0.1"/>
      <origin xyz="0 0 0"/>
      <inertia ixx="0.012411765597" ixy="-0.000711733678" ixz="0.00050272983" iyy="0.015218160428" iyz="-0.000004273467" izz="0.011763977943"/>
    </inertial>
  </link>
  <joint name="wheel_joint_fr" type="continuous">
    <axis xyz="0 1 0"/>
    <limit effort="30" velocity="10"/>
    <dynamics damping="1.0" friction="1.0"/>
    <safety_controller k_velocity="10.0"/>
    <origin rpy="0 0 0" xyz="0.0 0.0 0.0"/>
    <parent link="caster_link_fr"/>
    <child link="wheel_link_fr"/>
  </joint>
  <link name="wheel_link_fr">
    <inertial>
      <mass value="1.4"/>
      <origin xyz="0 0 0"/>
      <inertia ixx="0.012411765597" ixy="-0.000711733678" ixz="0.00050272983" iyy="0.015218160428" iyz="-0.000004273467" izz="0.011763977943"/>
    </inertial>
    <visual>
      <origin rpy="0 0 0" xyz="0 0 0"/>
      <geometry>
        <!--<mesh filename="package://youbot_description/meshes/youbot_base/youbot_wheel.stl" />-->
        <sphere radius="0.0475"/>
      </geometry>
      <material name="youBot/Orange"/>
    </visual>
    <collision>
      <origin rpy="1.57079632679 0 0" xyz="0 0 0"/>
      <geometry>
        <cylinder length="0.0475" radius="0.0475"/>
      </geometry>
    </collision>
  </link>
  <!-- back left wheel -->
  <joint name="caster_joint_bl" type="continuous">
    <origin rpy="0 0 0" xyz="-0.228 0.158 -0.034"/>
    <axis xyz="0 0 1"/>
    <limit effort="30" velocity="10"/>
    <dynamics damping="1.0" friction="1.0"/>
    <safety_controller k_velocity="10.0"/>
    <parent link="base_link"/>
    <child link="caster_link_bl"/>
  </joint>
  <link name="caster_link_bl">
    <inertial>
      <mass value="0.1"/>
      <origin xyz="0 0 0"/>
      <inertia ixx="0.012411765597" ixy="-0.000711733678" ixz="0.00050272983" iyy="0.015218160428" iyz="-0.000004273467" izz="0.011763977943"/>
    </inertial>
  </link>
  <joint name="wheel_joint_bl" type="continuous">
    <axis xyz="0 1 0"/>
    <limit effort="10" velocity="10"/>
    <limit effort="30" velocity="10"/>
    <dynamics damping="1.0" friction="1.0"/>
    <safety_controller k_velocity="10.0"/>
    <origin rpy="0 0 0" xyz="0.0 0.0 0.0"/>
    <parent link="caster_link_bl"/>
    <child link="wheel_link_bl"/>
  </joint>
  <link name="wheel_link_bl">
    <inertial>
      <mass value="1.4"/>
      <origin xyz="0 0 0"/>
      <inertia ixx="0.012411765597" ixy="-0.000711733678" ixz="0.00050272983" iyy="0.015218160428" iyz="-0.000004273467" izz="0.011763977943"/>
    </inertial>
    <visual>
      <origin rpy="0 0 0" xyz="0 0 0"/>
      <geometry>
        <!--<mesh filename="package://youbot_description/meshes/youbot_base/youbot_wheel.stl" />-->
        <sphere radius="0.0475"/>
      </geometry>
      <material name="youBot/Orange"/>
    </visual>
    <collision>
      <origin rpy="1.57079632679 0 0" xyz="0 0 0"/>
      <geometry>
        <cylinder length="0.0475" radius="0.0475"/>
      </geometry>
    </collision>
  </link>
  <!-- back right wheel -->
  <joint name="caster_joint_br" type="continuous">
    <origin rpy="0 0 0" xyz="-0.228 -0.158 -0.034"/>
    <axis xyz="0 0 1"/>
    <limit effort="30" velocity="10"/>
    <dynamics damping="1.0" friction="1.0"/>
    <safety_controller k_velocity="10.0"/>
    <parent link="base_link"/>
    <child link="caster_link_br"/>
  </joint>
  <link name="caster_link_br">
    <inertial>
      <mass value="0.1"/>
      <origin xyz="0 0 0"/>
      <inertia ixx="0.012411765597" ixy="-0.000711733678" ixz="0.00050272983" iyy="0.015218160428" iyz="-0.000004273467" izz="0.011763977943"/>
    </inertial>
  </link>
  <joint name="wheel_joint_br" type="continuous">
    <axis xyz="0 1 0"/>
    <limit effort="30" velocity="10"/>
    <dynamics damping="1.0" friction="1.0"/>
    <safety_controller k_velocity="10.0"/>
    <origin rpy="0 0 0" xyz="0.0 0.0 0.0"/>
    <parent link="caster_link_br"/>
    <child link="wheel_link_br"/>
  </joint>
  <link name="wheel_link_br">
    <inertial>
      <mass value="1.4"/>
      <origin xyz="0 0 0"/>
      <inertia ixx="0.012411765597" ixy="-0.000711733678" ixz="0.00050272983" iyy="0.015218160428" iyz="-0.000004273467" izz="0.011763977943"/>
    </inertial>
    <visual>
      <origin rpy="0 0 0" xyz="0 0 0"/>
      <geometry>
        <!--<mesh filename="package://youbot_description/meshes/youbot_base/youbot_wheel.stl" />-->
        <sphere radius="0.0475"/>
      </geometry>
      <material name="youBot/Orange"/>
    </visual>
    <collision>
      <origin rpy="1.57079632679 0 0" xyz="0 0 0"/>
      <geometry>
        <cylinder length="0.0475" radius="0.0475"/>
      </geometry>
    </collision>
  </link>
  <!-- extensions -->
  <gazebo reference="youbot_base">
    </gazebo>
  <!-- front left wheel -->
  <gazebo reference="wheel_link_fl">
    <kp>1000000</kp>
    <kd>100</kd>
  </gazebo>
  <gazebo reference="caster_link_fl">
    </gazebo>
  <!-- front right wheel -->
  <gazebo reference="wheel_link_fr">
    <kp>1000000</kp>
    <kd>100</kd>
  </gazebo>
  <gazebo reference="caster_link_fr">   
    </gazebo>
  <!-- back left wheel -->
  <gazebo reference="wheel_link_bl">
    <kp>1000000</kp>
    <kd>100</kd>
  </gazebo>
  <gazebo reference="caster_link_bl">
    </gazebo>
  <!-- back right wheel -->
  <gazebo reference="wheel_link_br">
    <kp>1000000</kp>
    <kd>100</kd>
  </gazebo>
  <gazebo reference="caster_link_br">
    </gazebo>
  <!-- front left wheel -->
  <transmission name="wheel_trans_fl">
    <type>transmission_interface/SimpleTransmission</type>
    <actuator name="wheel_motor_fl">
      <hardwareInterface>VelocityJointInterface</hardwareInterface>
      <mechanicalReduction>79.2380952381</mechanicalReduction>
    </actuator>
    <joint name="wheel_joint_fl"/>
  </transmission>
  <transmission name="caster_trans_fl">
    <type>transmission_interface/SimpleTransmission</type>
    <actuator name="caster_motor_fl">
      <hardwareInterface>VelocityJointInterface</hardwareInterface>
      <mechanicalReduction>79.2380952381</mechanicalReduction>
    </actuator>
    <joint name="caster_joint_fl"/>
  </transmission>
  <!-- front right wheel -->
  <transmission name="wheel_trans_fr">
    <type>transmission_interface/SimpleTransmission</type>
    <actuator name="wheel_motor_fr">
      <hardwareInterface>VelocityJointInterface</hardwareInterface>
      <mechanicalReduction>79.2380952381</mechanicalReduction>
    </actuator>
    <joint name="wheel_joint_fr"/>
  </transmission>
  <transmission name="caster_trans_fr">
    <type>transmission_interface/SimpleTransmission</type>
    <actuator name="caster_motor_fr">
      <hardwareInterface>VelocityJointInterface</hardwareInterface>
      <mechanicalReduction>79.2380952381</mechanicalReduction>
    </actuator>
    <joint name="caster_joint_fr"/>
  </transmission>
  <!-- back left wheel -->
  <transmission name="wheel_trans_bl">
    <type>transmission_interface/SimpleTransmission</type>
    <actuator name="wheel_motor_bl">
      <hardwareInterface>VelocityJointInterface</hardwareInterface>
      <mechanicalReduction>79.2380952381</mechanicalReduction>
    </actuator>
    <joint name="wheel_joint_bl"/>
  </transmission>
  <transmission name="caster_trans_bl">
    <type>transmission_interface/SimpleTransmission</type>
    <actuator name="caster_motor_bl">
      <hardwareInterface>VelocityJointInterface</hardwareInterface>
      <mechanicalReduction>79.2380952381</mechanicalReduction>
    </actuator>
    <joint name="caster_joint_bl"/>
  </transmission>
  <!-- back right wheel -->
  <transmission name="wheel_trans_br">
    <type>transmission_interface/SimpleTransmission</type>
    <actuator name="wheel_motor_br">
      <hardwareInterface>VelocityJointInterface</hardwareInterface>
      <mechanicalReduction>79.2380952381</mechanicalReduction>
    </actuator>
    <joint name="wheel_joint_br"/>
  </transmission>
  <transmission name="caster_trans_br">
    <type>transmission_interface/SimpleTransmission</type>
    <actuator name="caster_motor_br">
      <hardwareInterface>VelocityJointInterface</hardwareInterface>
      <mechanicalReduction>79.2380952381</mechanicalReduction>
    </actuator>
    <joint name="caster_joint_br"/>
  </transmission>
  <!-- joint between arm_7_link and sdh_palm_link -->
  <joint name="plate_joint" type="fixed">
    <origin rpy="0 0 0" xyz="-0.159 0 0.046"/>
    <parent link="base_link"/>
    <child link="plate_link"/>
  </joint>
  <link name="plate_link">
    <inertial>
      <origin rpy="0 0 0" xyz="0 0 0"/>
      <mass value="2.397"/>
      <inertia ixx="0.01" ixy="0" ixz="0" iyy="0.01" iyz="0" izz="0.01"/>
    </inertial>
    <visual>
      <origin rpy="0 0 0" xyz="0 0 0"/>
      <geometry>
        <mesh filename="package://youbot_description/meshes/youbot_plate/plate.dae"/>
      </geometry>
      <material name="DarkGrey"/>
    </visual>
    <collision>
      <origin rpy="0 0 0" xyz="0 0 0"/>
      <geometry>
        <mesh filename="package://youbot_description/meshes/youbot_plate/plate_convex.dae"/>
      </geometry>
    </collision>
  </link>
  <!-- extensions -->
  <!-- joint between base_link and arm_0_link -->
  <joint name="arm_joint_0" type="fixed">
    <origin rpy="0 0 0" xyz="0.143 0 0.046"/>
    <parent link="base_link"/>
    <child link="arm_link_0"/>
  </joint>
  <link name="arm_link_0">
    <inertial>
      <!--<origin xyz="0.023 0 0.006" rpy="0 0 0"/>-->
      <origin rpy="0 0 0" xyz="0 0 0"/>
      <mass value="0.961"/>
      <inertia ixx="0.01" ixy="0" ixz="0" iyy="0.01" iyz="0" izz="0.01"/>
    </inertial>
    <visual>
      <origin rpy="0 0 0" xyz="0 0 0"/>
      <geometry>
        <mesh filename="package://youbot_description/meshes/youbot_arm/arm0.dae"/>
      </geometry>
      <material name="youBot/DarkGrey"/>
    </visual>
    <collision>
      <!--<origin xyz="0.023 0 0.006" rpy="0 0 0"/>-->
      <origin rpy="0 0 0" xyz="0 0 0"/>
      <geometry>
        <mesh filename="package://youbot_description/meshes/youbot_arm/arm0_convex.dae"/>
        <!--<cylinder length="0.078" radius="0.093"/>-->
      </geometry>
    </collision>
  </link>
  <!-- joint between arm_0_link and arm_1_link -->
  <joint name="arm_joint_1" type="revolute">
    <origin rpy="0 0 2.96705972839" xyz="0.024 0 0.096"/>
    <parent link="arm_link_0"/>
    <child link="arm_link_1"/>
    <axis xyz="0 0 -1"/>
    <!--<calibration rising="${arm_1_ref}" falling="${arm_1_ref}"/>-->
    <dynamics damping="1" friction="1"/>
    <!-- damping - N*s/m, N*s*m/rad -->
    <!-- friction - N, N*m -->
    <limit effort="9.5" lower="0" upper="5.89921287174" velocity="1.57079632679"/>
    <!--effort - N, N*m-->
    <!--velocity - m/s, rad/s-->
    <!--safety_controller k_position="20" k_velocity="${9.5/M_PI / 2.0}" soft_lower_limit="${threshold}" soft_upper_limit="${joint_1_limit_soft}" /-->
    <!--k_position N/m, N/rad-->
    <!--k_velocity N*s/m, N*s*m/rad-->
    <!--for details: http://www.ros.org/wiki/pr2_controller_manager/safety_limits-->
  </joint>
  <link name="arm_link_1">
    <inertial>
      <mass value="1.39"/>
      <origin rpy="0 0 0" xyz="0.01489 0.00213 0.00213"/>
      <inertia ixx="0.0029525" ixy="0.0" ixz="0.0" iyy="0.0060091" iyz="0.0" izz="0.0058821"/>
    </inertial>
    <visual>
      <origin rpy="0 0 0" xyz="0 0 0"/>
      <geometry>
        <mesh filename="package://youbot_description/meshes/youbot_arm/arm1.dae"/>
      </geometry>
      <material name="youBot/Orange"/>
    </visual>
    <collision>
      <!--<origin xyz="0 0 -0.003" rpy="0 0 0" />-->
      <origin rpy="0 0 0" xyz="0 0 0"/>
      <geometry>
        <mesh filename="package://youbot_description/meshes/youbot_arm/arm1_convex.dae"/>
        <!--<cylinder length="0.102" radius="0.080"/>-->
      </geometry>
    </collision>
  </link>
  <!-- joint between arm_1_link and arm_2_link -->
  <joint name="arm_joint_2" type="revolute">
    <origin rpy="0 -1.1344640138 0" xyz="0.033 0 0.019"/>
    <parent link="arm_link_1"/>
    <child link="arm_link_2"/>
    <axis xyz="0 1 0"/>
    <!--<calibration rising="${arm_2_ref}" falling="${arm_2_ref}"/>-->
    <dynamics damping="1" friction="1"/>
    <limit effort="9.5" lower="0" upper="2.70526034059" velocity="1.57079632679"/>
    <!--safety_controller k_position="20" k_velocity="${2*9.5/M_PI}" soft_lower_limit="${threshold}" soft_upper_limit="${joint_2_limit_soft}" /-->
  </joint>
  <link name="arm_link_2">
    <inertial>
      <mass value="1.318"/>
      <origin rpy="0 0 0" xyz="0.01053 -0.0307 0.08597"/>
      <inertia ixx="0.0031145" ixy="0.0" ixz="0.0" iyy="0.0005843" iyz="0.0" izz="0.0031631"/>
    </inertial>
    <visual>
      <origin rpy="0 0 0" xyz="0 -0.032 0.078"/>
      <geometry>
        <mesh filename="package://youbot_description/meshes/youbot_arm/arm2.dae"/>
      </geometry>
    </visual>
    <collision>
      <!--<origin xyz="0.001 -0.041 0.074" rpy="0 0 0" />-->
      <origin rpy="0 0 0" xyz="0 -0.032 0.078"/>
      <geometry>
        <mesh filename="package://youbot_description/meshes/youbot_arm/arm2_convex.dae"/>
        <!--<box size="0.074 0.082 0.222"/>-->
      </geometry>
    </collision>
  </link>
  <!-- joint between arm_2_link and arm_3_link -->
  <!--<joint name="${name}_joint_3" type="revolute">
			<origin xyz="0.000 0.000 0.155" rpy="0 ${146 * M_PI / 180} 0"/>
			<parent link="${name}_link_2"/>
			<child link="${name}_link_3"/>
			<axis xyz="0 1 0"/>
			<dynamics damping="1" friction="1" />
			<limit effort="${6}" velocity="${M_PI / 2.0}" lower="-${joint_3_limit}" upper="0"/>
      <safety_controller k_position="20" k_velocity="50" soft_lower_limit="-${joint_3_limit_soft}" soft_upper_limit="${threshold}" />
		</joint>-->
  <joint name="arm_joint_3" type="revolute">
    <origin rpy="0 2.54818070791 0" xyz="0.000 0.000 0.155"/>
    <parent link="arm_link_2"/>
    <child link="arm_link_3"/>
    <axis xyz="0 1 0"/>
    <dynamics damping="1" friction="1"/>
    <limit effort="6.0" lower="-5.18362787842" upper="0" velocity="1.57079632679"/>
    <!--safety_controller k_position="20" k_velocity="50" soft_lower_limit="-${joint_3_limit_soft}" soft_upper_limit="-${threshold}" /-->
  </joint>
  <link name="arm_link_3">
    <inertial>
      <mass value="0.821"/>
      <origin rpy="0 0 0" xyz="0.0001 0.0207 0.07107"/>
      <inertia ixx="0.00172767" ixy="0.0" ixz="0.0" iyy="0.00041967" iyz="0.0" izz="0.0018468"/>
    </inertial>
    <visual>
      <origin rpy="0 0 0" xyz="0.000 0.028 0.079"/>
      <geometry>
        <mesh filename="package://youbot_description/meshes/youbot_arm/arm3.dae"/>
      </geometry>
      <material name="youBot/Orange"/>
    </visual>
    <collision>
      <!--<origin xyz="0.000 0.025 0.067" rpy="0 0 0" />-->
      <origin rpy="0 0 0" xyz="0.000 0.028 0.079"/>
      <geometry>
        <mesh filename="package://youbot_description/meshes/youbot_arm/arm3_convex.dae"/>
        <!--<box size="0.064 0.054 0.192"/>-->
      </geometry>
    </collision>
  </link>
  <!-- joint between arm_3_link and arm_4_link -->
  <joint name="arm_joint_4" type="revolute">
    <origin rpy="0 -1.78896248329 0" xyz="0.000 0.000 0.135"/>
    <parent link="arm_link_3"/>
    <child link="arm_link_4"/>
    <axis xyz="0 1 0"/>
    <!--<calibration rising="${arm_4_ref}" falling="${arm_4_ref}"/>-->
    <dynamics damping="1" friction="1"/>
    <limit effort="2.0" lower="0" upper="3.57792496659" velocity="1.57079632679"/>
    <!--safety_controller k_position="20" k_velocity="100" soft_lower_limit="0" soft_upper_limit="${joint_4_limit_soft}" /-->
  </joint>
  <link name="arm_link_4">
    <inertial>
      <mass value="0.769"/>
      <origin rpy="0 0 0" xyz="0.00011 -0.02 0.05019"/>
      <inertia ixx="0.0006764" ixy="0.0" ixz="0.0" iyy="0.0010573" iyz="0.0" izz="0.0006610"/>
    </inertial>
    <visual>
      <origin rpy="0 0 0" xyz="0 -0.010 0.029"/>
      <geometry>
        <mesh filename="package://youbot_description/meshes/youbot_arm/arm4.dae"/>
      </geometry>
      <material name="youBot/Orange"/>
    </visual>
    <collision>
      <!--<origin xyz="0 0 0.026" rpy="0 0 0" />-->
      <origin rpy="0 0 0" xyz="0 -0.010 0.029"/>
      <geometry>
        <mesh filename="package://youbot_description/meshes/youbot_arm/arm4_convex.dae"/>
        <!--<box size="0.058 0.100 0.118"/>-->
      </geometry>
    </collision>
  </link>
  <!-- joint between arm_4_link and arm_5_link -->
  <joint name="arm_joint_5" type="revolute">
    <origin rpy="0 0 2.92342649709" xyz="-0.002 0 0.130"/>
    <parent link="arm_link_4"/>
    <child link="arm_link_5"/>
    <axis xyz="0 0 -1"/>
    <!--<calibration rising="${arm_5_ref}" falling="${arm_5_ref}"/>-->
    <dynamics damping="1" friction="1"/>
    <limit effort="1.0" lower="0" upper="5.84685299418" velocity="1.57079632679"/>
    <!--safety_controller k_position="20" k_velocity="100" soft_lower_limit="0" soft_upper_limit="${joint_5_limit_soft}" /-->
  </joint>
  <link name="arm_link_5">
    <inertial>
      <mass value="0.687"/>
      <origin rpy="0 0 0" xyz="0.0 0.00115 -0.01683"/>
      <inertia ixx="0.0001934" ixy="0.0" ixz="0.0" iyy="0.0001602" iyz="0.0" izz="0.0000689"/>
    </inertial>
    <visual>
      <origin rpy="0 0 0" xyz="0.003 0 -0.034"/>
      <geometry>
        <mesh filename="package://youbot_description/meshes/youbot_arm/arm5.dae"/>
      </geometry>
      <material name="youBot/DarkGrey"/>
    </visual>
    <collision>
      <origin rpy="0 0 0" xyz="0.003 0 -0.034"/>
      <geometry>
        <mesh filename="package://youbot_description/meshes/youbot_arm/arm5_convex.dae"/>
        <!--<box size="0.054 0.096 0.030"/>-->
      </geometry>
    </collision>
  </link>
  <!-- extensions -->
  <gazebo reference="arm_link_0">
    <turnGravityOff>false</turnGravityOff>
  </gazebo>
  <gazebo reference="arm_link_1">
    <turnGravityOff>false</turnGravityOff>
  </gazebo>
  <gazebo reference="arm_link_2">
    <turnGravityOff>false</turnGravityOff>
  </gazebo>
  <gazebo reference="arm_link_3">
    <turnGravityOff>false</turnGravityOff>
  </gazebo>
  <gazebo reference="arm_link_4">
    <turnGravityOff>false</turnGravityOff>
  </gazebo>
  <gazebo reference="arm_link_5">
    <turnGravityOff>false</turnGravityOff>
  </gazebo>
  <transmission name="arm_trans_1">
    <type>transmission_interface/SimpleTransmission</type>
    <actuator name="arm_motor_1">
      <hardwareInterface>EffortJointInterface</hardwareInterface>
      <mechanicalReduction>1</mechanicalReduction>
    </actuator>
    <joint name="arm_joint_1"/>
  </transmission>
  <transmission name="arm_trans_2">
    <type>transmission_interface/SimpleTransmission</type>
    <actuator name="arm_motor_2">
      <hardwareInterface>EffortJointInterface</hardwareInterface>
      <mechanicalReduction>1</mechanicalReduction>
    </actuator>
    <joint name="arm_joint_2"/>
  </transmission>
  <transmission name="arm_trans_3">
    <type>transmission_interface/SimpleTransmission</type>
    <actuator name="arm_motor_3">
      <hardwareInterface>EffortJointInterface</hardwareInterface>
      <mechanicalReduction>1</mechanicalReduction>
    </actuator>
    <joint name="arm_joint_3"/>
  </transmission>
  <transmission name="arm_trans_4">
    <type>transmission_interface/SimpleTransmission</type>
    <actuator name="arm_motor_4">
      <hardwareInterface>EffortJointInterface</hardwareInterface>
      <mechanicalReduction>1</mechanicalReduction>
    </actuator>
    <joint name="arm_joint_4"/>
  </transmission>
  <transmission name="arm_trans_5">
    <type>transmission_interface/SimpleTransmission</type>
    <actuator name="arm_motor_5">
      <hardwareInterface>EffortJointInterface</hardwareInterface>
      <mechanicalReduction>1</mechanicalReduction>
    </actuator>
    <joint name="arm_joint_5"/>
  </transmission>
  <!-- joint between arm_7_link and sdh_palm_link -->
  <joint name="gripper_palm_joint" type="fixed">
    <origin rpy="0 0 0" xyz="0 0 0"/>
    <parent link="arm_link_5"/>
    <child link="gripper_palm_link"/>
  </joint>
  <link name="gripper_palm_link">
    <inertial>
      <origin rpy="0 0 0" xyz="0 0 0"/>
      <mass value="0.1"/>
      <inertia ixx="0.01" ixy="0" ixz="0" iyy="0.01" iyz="0" izz="0.01"/>
    </inertial>
    <visual>
      <origin rpy="0 0 0" xyz="0 0 0"/>
      <geometry>
        <mesh filename="package://youbot_description/meshes/youbot_gripper/palm.dae"/>
      </geometry>
      <material name="Black"/>
    </visual>
    <collision>
      <origin rpy="0 0 0" xyz="0 0 0"/>
      <geometry>
        <!--<box size="0.050 0.094 0.054"/>-->
        <mesh filename="package://youbot_description/meshes/youbot_gripper/palm_convex.dae"/>
      </geometry>
    </collision>
  </link>
  <joint name="gripper_finger_joint_l" type="prismatic">
    <origin rpy="0 0 3.14159265359" xyz="0.004 0.008 0.046"/>
    <parent link="gripper_palm_link"/>
    <child link="gripper_finger_link_l"/>
    <axis xyz="0 -1 0"/>
    <dynamics damping="1.0" friction="1.0"/>
    <limit effort="1" lower="0" upper="0.0115" velocity="0.1"/>
    <safety_controller k_position="20" k_velocity="25" soft_lower_limit="0.001" soft_upper_limit="0.011"/>
  </joint>
  <link name="gripper_finger_link_l">
    <inertial>
      <origin rpy="0 0 0" xyz="0 -0.001 0"/>
      <mass value="0.01"/>
      <inertia ixx="0.01" ixy="0" ixz="0" iyy="0.01" iyz="0" izz="0.01"/>
    </inertial>
    <visual>
      <origin rpy="0 0 0" xyz="0 0 0"/>
      <geometry>
        <mesh filename="package://youbot_description/meshes/youbot_gripper/finger.dae"/>
      </geometry>
      <material name="Black"/>
    </visual>
    <collision>
      <origin rpy="0 0 0" xyz="0 0 0"/>
      <geometry>
        <!--<box size="0.014 0.020 0.046"/>-->
        <mesh filename="package://youbot_description/meshes/youbot_gripper/finger_convex.dae"/>
      </geometry>
    </collision>
  </link>
  <joint name="gripper_finger_joint_r" type="prismatic">
    <origin rpy="0 0 0" xyz="0.004 -0.008 0.046"/>
    <parent link="gripper_palm_link"/>
    <child link="gripper_finger_link_r"/>
    <axis xyz="0 -1 0"/>
    <dynamics damping="1.0" friction="1.0"/>
    <limit effort="1" lower="0" upper="0.0115" velocity="0.1"/>
    <safety_controller k_position="20" k_velocity="25" soft_lower_limit="0.001" soft_upper_limit="0.011"/>
  </joint>
  <link name="gripper_finger_link_r">
    <inertial>
      <origin rpy="0 0 0" xyz="0.000 -0.001 0"/>
      <mass value="0.01"/>
      <inertia ixx="0.01" ixy="0" ixz="0" iyy="0.01" iyz="0" izz="0.01"/>
    </inertial>
    <visual>
      <origin rpy="0 0 0" xyz="0 0 0"/>
      <geometry>
        <mesh filename="package://youbot_description/meshes/youbot_gripper/finger.dae"/>
      </geometry>
      <material name="Black"/>
    </visual>
    <collision>
      <origin rpy="0 0 0" xyz="0.000 0 0"/>
      <geometry>
        <!--<box size="0.014 0.020 0.046"/>-->
        <mesh filename="package://youbot_description/meshes/youbot_gripper/finger_convex.dae"/>
      </geometry>
    </collision>
  </link>
  <!-- extensions -->
  <gazebo reference="gripper_palm_link">
    <material>Gazebo/Black</material>
    <turnGravityOff>false</turnGravityOff>
    <selfCollide>true</selfCollide>
  </gazebo>
  <gazebo reference="gripper_finger_l_link">
    <material>Gazebo/Black</material>
    <turnGravityOff>false</turnGravityOff>
    <selfCollide>true</selfCollide>
  </gazebo>
  <gazebo reference="gripper_finger_r_link">
    <material>Gazebo/Black</material>
    <turnGravityOff>false</turnGravityOff>
    <selfCollide>true</selfCollide>
  </gazebo>
  <transmission name="gripper_finger_l_trans">
    <type>transmission_interface/SimpleTransmission</type>
    <actuator name="gripper_finger_l_motor">
      <hardwareInterface>EffortJointInterface</hardwareInterface>
      <mechanicalReduction>1</mechanicalReduction>
    </actuator>
    <joint name="gripper_finger_joint_l"/>
  </transmission>
  <transmission name="gripper_finger_r_trans">
    <type>transmission_interface/SimpleTransmission</type>
    <actuator name="gripper_finger_r_motor">
      <hardwareInterface>EffortJointInterface</hardwareInterface>
      <mechanicalReduction>1</mechanicalReduction>
    </actuator>
    <joint name="gripper_finger_joint_r"/>
  </transmission>
  <!-- base laser front -->
  <joint name="base_laser_front_hokuyo_urg04_laser_joint" type="fixed">
    <axis xyz="0 1 0"/>
    <origin rpy="0 0 0" xyz="0.3 0 -0.03"/>
    <parent link="base_link"/>
    <child link="base_laser_front_link"/>
  </joint>
  <link name="base_laser_front_link" type="laser">
    <inertial>
      <mass value="0.16"/>
      <origin rpy="0 0 0" xyz="0 0 0"/>
      <inertia ixx="0.1" ixy="0" ixz="0" iyy="0.1" iyz="0" izz="0.1"/>
    </inertial>
    <visual>
      <origin rpy="0 0 0" xyz="0 0 0"/>
      <geometry>
        <mesh filename="package://youbot_description/meshes/sensors/hokuyo.dae"/>
      </geometry>
      <material name="DarkGrey"/>
    </visual>
    <collision>
      <origin rpy="0 0 0" xyz="0 0 0"/>
      <geometry>
        <mesh filename="package://youbot_description/meshes/sensors/hokuyo_convex.dae"/>
      </geometry>
    </collision>
  </link>
  <!-- gazebo extensions -->
  <gazebo reference="base_laser_front_link">
    <sensor name="base_laser_front" type="ray">
      <always_on>true</always_on>
      <update_rate>10</update_rate>
      <pose>0 0 0 0 0 0</pose>
      <visualize>false</visualize>
      <ray>
        <scan>
          <horizontal>
            <samples>150</samples>
            <resolution>1.0</resolution>
            <min_angle>-1.57</min_angle>
            <max_angle>1.57</max_angle>
          </horizontal>
        </scan>
        <range>
          <min>0.05</min>
          <max>5.6</max>
          <resolution>0.36</resolution>
        </range>
      </ray>
      <plugin filename="libgazebo_ros_laser.so" name="gazebo_ros_base_laser_front_controller">
        <gaussianNoise>0.005</gaussianNoise>
        <alwaysOn>true</alwaysOn>
        <updateRate>10</updateRate>
        <topicName>scan_front</topicName>
        <frameName>/base_laser_front_link</frameName>
      </plugin>
    </sensor>
  </gazebo>
</robot>

